INFO|2018-03-01 12:24:41|65064|140735593038656|_internal.py:88| * Running on http://0.0.0.0:8000/ (Press CTRL+C to quit)
ERROR|2018-03-01 12:24:57|65064|140735593038656|server.py:46|数据库插入失败: (1136, "Column count doesn't match value count at row 1")
INFO|2018-03-01 12:24:57|65064|140735593038656|server.py:47|{"action": "setup", "data": {"task_id": "123456abcdef", "task_args": {"key": "value"}, "ips": "192.168.1.1,192.168.1.2,192.168.1.3"}}
INFO|2018-03-01 12:24:57|65064|140735593038656|_internal.py:88|127.0.0.1 - - [01/Mar/2018 12:24:57] "POST /v1/task HTTP/1.1" 200 -
INFO|2018-03-01 12:25:47|65084|140735593038656|_internal.py:88| * Running on http://0.0.0.0:8000/ (Press CTRL+C to quit)
INFO|2018-03-01 12:25:49|65084|140735593038656|_internal.py:88|127.0.0.1 - - [01/Mar/2018 12:25:49] "POST /v1/task HTTP/1.1" 200 -
INFO|2018-03-02 10:36:34|73502|140735593038656|_internal.py:88| * Running on http://127.0.0.1:8000/ (Press CTRL+C to quit)
INFO|2018-03-02 10:36:46|73502|140735593038656|_internal.py:88|127.0.0.1 - - [02/Mar/2018 10:36:46] "GET /status HTTP/1.1" 200 -
INFO|2018-03-02 10:36:57|73502|140735593038656|_internal.py:88|127.0.0.1 - - [02/Mar/2018 10:36:57] "GET /v1/task/123456abcd HTTP/1.1" 200 -
INFO|2018-03-02 10:37:25|73502|140735593038656|_internal.py:88|127.0.0.1 - - [02/Mar/2018 10:37:25] "GET /v1/task/123456abcdef HTTP/1.1" 200 -
INFO|2018-03-02 10:39:39|73502|140735593038656|_internal.py:88|127.0.0.1 - - [02/Mar/2018 10:39:39] "GET /v1/task/26b2551b09564a43b91af27366a460d2 HTTP/1.1" 200 -
